Workbook
Name amortization_term: #REF!
Name interest_rate: #REF!
Name lease_term: #REF!
Name loan_amount: #REF!
Name Op_exp: #REF!
Name points: #REF!
Name prop_taxes: #REF!
Name Purchase_price: #REF!
Name rent_1: #REF!
Name rent_2: #REF!
Name rent_3: #REF!
Name rent_4: #REF!
Name Square_feet: #REF!

Sheet Assumptions
A1: DLP CASE STUDY
A2: DLP Capital needs to make a decision about purchasing a 300 unit mixed use apartment community in St. Augustine, FL.
A3: Create a monthly discounted cash flow (DCF) model with annual summaries for the property and show each of the metrics listed below. Create this spreadsheet from scratch (do not use a pre-existing template) and do not consult with any individuals outside DLP.
A4: Create your written outputs without using ChatGPT or other AI.
A5: Your model needs to be dynamic, so if ANY of the assumptions are changed, the cash flows will be updated accordingly
A7: Outputs / Metrics to Calculate | E7: Outputs / Written
A8: Unlevered / Levered / Net Levered IRR | C8: TRUE | E8: Should DLP move forward with this deal? Why? Is this a "Good Deal?"
A9: Profit and Equity Multiple to Investors | C9: TRUE | E9: Is this a stable asset? Why or why not? Is this a Value Add, Core Plus, or Core investment profile? Why? Levered DSCR
A10: Cash on Cash and Return on Cost Returns | C10: TRUE | E10: What are some things you would look to do at this property immediately after closing?
A11: Sensitivity tables for value based on cap rate and rent growth | C11: TRUE | E11: What additional information would you need to perform a more complete analysis?
A14: MODELING EXAMINATION ASSUMPTIONS
A16: Deal Summary | E16: Financing Assumptions | J16: 2024 Income Statement
A17: Deal Name | B17: DREAM Apartments | E17: Leverage (Loan to Value %) | H17: 0.6 | J17: Gross Potential Rent (GPR) | L17: 4200000
A18: Location | B18: St. Augustine, FL | E18: Fixed Rate | H18: 0.065 | J18: Loss to Lease | L18: -15000
A19: Class | B19: A | E19: Interest Only (Yrs) | H19: 2 | J19: Commercial Rent | L19: 93750
A20: Address | B20: 1000 West Place | E20: Amortization (Yrs) | H20: 30 | J20: Commercial Vacancy | L20: -9375
A21: Year Built | B21: 2023 | E21: Financing Fees | H21: 0.01 | J21: CAM | L21: 15000
A22: Current Occupancy | B22: 0.85 | E22: Term (Yrs) | H22: 7 | J22: Other Income | L22: 125000
A23: Units | B23: 300 | E23: Loan Amount | H23: =B32*H17 -> 12000000 | J23: TOTAL GROSS REVENUE | L23: 4409375
A24: Commercial SqFt | B24: 3750 | J24: Residential Vacancy | L24: -800000
A25: Current Rent | B25: 1250 | J25: Concessions | L25: -400000
A26: Commercial Rent | B26: 25 | E26: Waterfall Assumptions | J26: Bad Debt / Non. Rev Units | L26: -110485
A27: Commercial Vacancy | B27: 0.1 | E27: Asset Management Fee (% of Equity) | H27: 0.01 | J27: EFFECTIVE GROSS REVENUE | L27: 3098890
A28: CAM | B28: 4 | E28: Investor Threshold return before Promote | H28: 0.075 | J28: Real Estate Taxes | L28: -799318
E29: Promote | H29: 0.25 | J29: Insurance | L29: -125785
A30: Acquisition / Exit Assumptions | J30: Management Fee | L30: -122556
A31: Closing Date | B31: 46023 | J31: Controllable Operating Expenses | L31: -927010
A32: Acquisition Price | B32: 20000000 | J32: TOTAL OPEX | L32: -1974669
A33: Acquisition Costs | B33: 0.02 | J33: Capex Reserve | L33: -45000
A34: Sales Costs | B34: 0.02 | E34: Preferred Equity | J34: NET OPERATING INCOME | L34: 1079221
A35: Hold Period (Yrs) | B35: 7 | E35: Amount | H35: 2000000 | J35: Capital Improvements | L35: -35000
A36: Exit Cap Rate | B36: 0.055 | E36: Rate | H36: 0.09 | J36: COMBINED NET CASH FLOW | L36: 1044221
A38: Operating Assumptions | C38: 1 | D38: 2 | E38: 3 | F38: 4 | G38: 5 | H38: 6 | I38: 7 | J38: 8 | K38: 9 | L38: 10 | M38: 11
A39: Rent Growth | C39: 0 | D39: 0.05 | E39: 0.04 | F39: 0.03 | G39: 0.03 | H39: 0.03 | I39: 0.03 | J39: 0.03 | K39: 0.03 | L39: 0.03 | M39: 0.03
A40: Loss-to-Lease | C40: 0.0075 | D40: 0.01 | E40: 0.01 | F40: 0.01 | G40: 0.01 | H40: 0.01 | I40: 0.01 | J40: 0.01 | K40: 0.01 | L40: 0.01 | M40: 0.01
A41: Commercial Rent Growth | C41: 0.02 | D41: 0.02 | E41: 0.02 | F41: 0.02 | G41: 0.02 | H41: 0.02 | I41: 0.02 | J41: 0.02 | K41: 0.02 | L41: 0.02 | M41: 0.02
A42: Commercial Vacancy | C42: 0.1 | D42: 0.1 | E42: 0.1 | F42: 0.1 | G42: 0.1 | H42: 0.1 | I42: 0.1 | J42: 0.1 | K42: 0.1 | L42: 0.1 | M42: 0.1
A43: CAM | C43: 0.03 | D43: 0.03 | E43: 0.03 | F43: 0.03 | G43: 0.03 | H43: 0.03 | I43: 0.03 | J43: 0.03 | K43: 0.03 | L43: 0.03 | M43: 0.03
A44: Vacancy | C44: 0.2 | D44: 0.15 | E44: 0.05 | F44: 0.05 | G44: 0.05 | H44: 0.05 | I44: 0.05 | J44: 0.05 | K44: 0.05 | L44: 0.05 | M44: 0.05
A45: Concessions | C45: 0.1 | D45: 0.05 | E45: 0.035 | F45: 0.02 | G45: 0.02 | H45: 0.02 | I45: 0.02 | J45: 0.02 | K45: 0.02 | L45: 0.02 | M45: 0.02
...

Sheet DCF Model
B2: DCF Model
B3: Acquisition Date | D3: =Assumptions!B31 -> 46023
B4: Exit Date | D4: 48579
B5: Units | D5: =Assumptions!B23 -> 300 | F5: 0 | G5: =$F$5+1 -> 1 | H5: =$F$5+1 -> 1 | I5: =$F$5+1 -> 1 | J5: =$F$5+1 -> 1 | K5: =$F$5+1 -> 1 | L5: =$F$5+1 -> 1 | M5: =$F$5+1 -> 1 | N5: =$F$5+1 -> 1 | ... R5: =$F$5+1 -> 1 | S5: =G5+1 -> 2 | T5: =H5+1 -> 2 | U5: =I5+1 -> 2 | V5: =J5+1 -> 2 | W5: =K5+1 -> 2 | X5: =L5+1 -> 2 | Y5: =M5+1 -> 2 | Z5: =N5+1 -> 2 | ... CX5: =CL5+1 -> 8
B6: Commercial SqFt | D6: =Assumptions!B24 -> 3750 | F6: 0 | G6: =F6+1 -> 1 | H6: =G6+1 -> 2 | I6: =H6+1 -> 3 | J6: =I6+1 -> 4 | K6: =J6+1 -> 5 | L6: =K6+1 -> 6 | M6: =L6+1 -> 7 | N6: =M6+1 -> 8 | ... CX6: =CW6+1 -> 96
B7: CAM | D7: =Assumptions!B28 -> 4 | F7: =D3 -> 46023 | G7: =EOMONTH(F7,0) -> 46053 | H7: =EOMONTH(G7,1) -> 46081 | I7: =EOMONTH(H7,1) -> 46112 | J7: =EOMONTH(I7,1) -> 46142 | K7: =EOMONTH(J7,1) -> 46173 | L7: =EOMONTH(K7,1) -> 46203 | M7: =EOMONTH(L7,1) -> 46234 | N7: =EOMONTH(M7,1) -> 46265 | O7: =EOMONTH(N7,1) -> 46295 | ... CX7: =EOMONTH(CW7,1) -> 48944
B9: Residential Monthly Rent $/Unit | D9: =Assumptions!B25 -> 1250 | F9: =1250 -> 1250 | G9: =F9*(1+G10) -> 1250 | H9: =G9*(1+H10) -> 1250 | I9: =H9*(1+I10) -> 1250 | J9: =I9*(1+J10) -> 1250 | K9: =J9*(1+K10) -> 1250 | L9: =K9*(1+L10) -> 1250 | M9: =L9*(1+M10) -> 1250 | N9: =M9*(1+N10) -> 1250 | ... CX9: =CW9*(1+CX10) -> 1582.4091
B10: Residential Rent Growth | F10: =Assumptions!$C$39 -> 0 | G10: =INDEX(Assumptions!$C$39:$M$39,MATCH('DCF Model'!G$5,Assumptions!$C$38:$M$38,0))*(G$5<>F$5) -> 0 | H10: =INDEX(Assumptions!$C$39:$M$39,MATCH('DCF Model'!H$5,Assumptions!$C$38:$M$38,0))*(H$5<>G$5) -> 0 | I10: =INDEX(Assumptions!$C$39:$M$39,MATCH('DCF Model'!I$5,Assumptions!$C$38:$M$38,0))*(I$5<>H$5) -> 0 | J10: =INDEX(Assumptions!$C$39:$M$39,MATCH('DCF Model'!J$5,Assumptions!$C$38:$M$38,0))*(J$5<>I$5) -> 0 | K10: =INDEX(Assumptions!$C$39:$M$39,MATCH('DCF Model'!K$5,Assumptions!$C$38:$M$38,0))*(K$5<>J$5) -> 0 | L10: =INDEX(Assumptions!$C$39:$M$39,MATCH('DCF Model'!L$5,Assumptions!$C$38:$M$38,0))*(L$5<>K$5) -> 0 | M10: =INDEX(Assumptions!$C$39:$M$39,MATCH('DCF Model'!M$5,Assumptions!$C$38:$M$38,0))*(M$5<>L$5) -> 0 | N10: =INDEX(Assumptions!$C$39:$M$39,MATCH('DCF Model'!N$5,Assumptions!$C$38:$M$38,0))*(N$5<>M$5) -> 0 | ... CX10: =INDEX(Assumptions!$C$39:$M$39,MATCH('DCF Model'!CX$5,Assumptions!$C$38:$M$38,0))*(CX$5<>CW$5) -> 0
B11: Commercial Monthly Rent $/PSF | D11: =Assumptions!B26/12 -> 2.0833333 | F11: =D11 -> 2.0833333 | G11: =F11*(1+G10) -> 2.0833333 | H11: =G11*(1+H10) -> 2.0833333 | I11: =H11*(1+I10) -> 2.0833333 | J11: =I11*(1+J10) -> 2.0833333 | K11: =J11*(1+K10) -> 2.0833333 | L11: =K11*(1+L10) -> 2.0833333 | M11: =L11*(1+M10) -> 2.0833333 | N11: =M11*(1+N10) -> 2.0833333 | ... CX11: =CW11*(1+CX10) -> 2.6373485
B12: Commercial Rent Growth | F12: =Assumptions!$C$39 -> 0 | G12: =INDEX(Assumptions!$C$41:$M$41,MATCH('DCF Model'!G$5,Assumptions!$C$38:$M$38,0))*(G$5<>F$5) -> 0.02 | H12: =INDEX(Assumptions!$C$41:$M$41,MATCH('DCF Model'!H$5,Assumptions!$C$38:$M$38,0))*(H$5<>G$5) -> 0 | I12: =INDEX(Assumptions!$C$41:$M$41,MATCH('DCF Model'!I$5,Assumptions!$C$38:$M$38,0))*(I$5<>H$5) -> 0 | J12: =INDEX(Assumptions!$C$41:$M$41,MATCH('DCF Model'!J$5,Assumptions!$C$38:$M$38,0))*(J$5<>I$5) -> 0 | K12: =INDEX(Assumptions!$C$41:$M$41,MATCH('DCF Model'!K$5,Assumptions!$C$38:$M$38,0))*(K$5<>J$5) -> 0 | L12: =INDEX(Assumptions!$C$41:$M$41,MATCH('DCF Model'!L$5,Assumptions!$C$38:$M$38,0))*(L$5<>K$5) -> 0 | M12: =INDEX(Assumptions!$C$41:$M$41,MATCH('DCF Model'!M$5,Assumptions!$C$38:$M$38,0))*(M$5<>L$5) -> 0 | N12: =INDEX(Assumptions!$C$41:$M$41,MATCH('DCF Model'!N$5,Assumptions!$C$38:$M$38,0))*(N$5<>M$5) -> 0 | ... CX12: =INDEX(Assumptions!$C$41:$M$41,MATCH('DCF Model'!CX$5,Assumptions!$C$38:$M$38,0))*(CX$5<>CW$5) -> 0
B14: 2024 Income Statement
B15: INCOME
B16: Residential Gross Potential Rent (GPR) | D16: =Assumptions!L17 -> 4200000 | G16: =G9*$D$5 -> 375000 | H16: =H9*$D$5 -> 375000 | I16: =I9*$D$5 -> 375000 | J16: =J9*$D$5 -> 375000 | K16: =K9*$D$5 -> 375000 | L16: =L9*$D$5 -> 375000 | M16: =M9*$D$5 -> 375000 | N16: =N9*$D$5 -> 375000 | ... CX16: =CX9*$D$5 -> 474722.73
B17: Commercial Effective Rent | D17: =Assumptions!L19 -> 93750 | G17: =G11*$D$6 -> 7812.5 | H17: =H11*$D$6 -> 7812.5 | I17: =I11*$D$6 -> 7812.5 | J17: =J11*$D$6 -> 7812.5 | K17: =K11*$D$6 -> 7812.5 | L17: =L11*$D$6 -> 7812.5 | M17: =M11*$D$6 -> 7812.5 | N17: =N11*$D$6 -> 7812.5 | ... CX17: =CX11*$D$6 -> 9890.0569
B18: Other Income (Yr) | D18: =Assumptions!L22 -> 125000 | G18: =D18/12 -> 10416.667 | H18: =G18*(1+INDEX(Assumptions!$C$43:$M$43,MATCH('DCF Model'!H5,Assumptions!$C$38:$M$38))*(H$5<>G$5)) -> 10416.667 | I18: =H18*(1+INDEX(Assumptions!$C$43:$M$43,MATCH('DCF Model'!I5,Assumptions!$C$38:$M$38))*(I$5<>H$5)) -> 10416.667 | J18: =I18*(1+INDEX(Assumptions!$C$43:$M$43,MATCH('DCF Model'!J5,Assumptions!$C$38:$M$38))*(J$5<>I$5)) -> 10416.667 | K18: =J18*(1+INDEX(Assumptions!$C$43:$M$43,MATCH('DCF Model'!K5,Assumptions!$C$38:$M$38))*(K$5<>J$5)) -> 10416.667 | L18: =K18*(1+INDEX(Assumptions!$C$43:$M$43,MATCH('DCF Model'!L5,Assumptions!$C$38:$M$38))*(L$5<>K$5)) -> 10416.667 | M18: =L18*(1+INDEX(Assumptions!$C$43:$M$43,MATCH('DCF Model'!M5,Assumptions!$C$38:$M$38))*(M$5<>L$5)) -> 10416.667 | N18: =M18*(1+INDEX(Assumptions!$C$43:$M$43,MATCH('DCF Model'!N5,Assumptions!$C$38:$M$38))*(N$5<>M$5)) -> 10416.667 | O18: =N18*(1+INDEX(Assumptions!$C$43:$M$43,MATCH('DCF Model'!O5,Assumptions!$C$38:$M$38))*(O$5<>N$5)) -> 10416.667 | ... CX18: =CW18*(1+INDEX(Assumptions!$C$43:$M$43,MATCH('DCF Model'!CX5,Assumptions!$C$38:$M$38))*(CX$5<>CW$5)) -> 12811.186
B19: CAM (Yr) | D19: =Assumptions!L21 -> 15000 | G19: =D19*(1+INDEX(Assumptions!$C$43:$M$43,MATCH(G5,Assumptions!$C$38:$M$38))*(G$5<>F$5))/12 -> 1287.5 | H19: =G19*(1+INDEX(Assumptions!$C$43:$M$43,MATCH(H5,Assumptions!$C$38:$M$38))*(H$5<>G$5)) -> 1287.5 | I19: =H19*(1+INDEX(Assumptions!$C$43:$M$43,MATCH(I5,Assumptions!$C$38:$M$38))*(I$5<>H$5)) -> 1287.5 | J19: =I19*(1+INDEX(Assumptions!$C$43:$M$43,MATCH(J5,Assumptions!$C$38:$M$38))*(J$5<>I$5)) -> 1287.5 | K19: =J19*(1+INDEX(Assumptions!$C$43:$M$43,MATCH(K5,Assumptions!$C$38:$M$38))*(K$5<>J$5)) -> 1287.5 | L19: =K19*(1+INDEX(Assumptions!$C$43:$M$43,MATCH(L5,Assumptions!$C$38:$M$38))*(L$5<>K$5)) -> 1287.5 | M19: =L19*(1+INDEX(Assumptions!$C$43:$M$43,MATCH(M5,Assumptions!$C$38:$M$38))*(M$5<>L$5)) -> 1287.5 | N19: =M19*(1+INDEX(Assumptions!$C$43:$M$43,MATCH(N5,Assumptions!$C$38:$M$38))*(N$5<>M$5)) -> 1287.5 | O19: =N19*(1+INDEX(Assumptions!$C$43:$M$43,MATCH(O5,Assumptions!$C$38:$M$38))*(O$5<>N$5)) -> 1287.5 | ... CL19: =CK19*(1+INDEX(Assumptions!$C$43:$M$43,MATCH(CL5,Assumptions!$C$38:$M$38))*(CL$5<>CK$5)) -> 1537.3423 | CM19: =CL19*(1+INDEX(Assumptions!$C$43:$M$43,MATCH('DCF Model'!CM5,Assumptions!$C$38:$M$38))*(CM$5<>CL$5)) -> 1583.4626 | CN19: =CM19*(1+INDEX(Assumptions!$C$43:$M$43,MATCH('DCF Model'!CN5,Assumptions!$C$38:$M$38))*(CN$5<>CM$5)) -> 1583.4626 | CO19: =CN19*(1+INDEX(Assumptions!$C$43:$M$43,MATCH('DCF Model'!CO5,Assumptions!$C$38:$M$38))*(CO$5<>CN$5)) -> 1583.4626 | CP19: =CO19*(1+INDEX(Assumptions!$C$43:$M$43,MATCH('DCF Model'!CP5,Assumptions!$C$38:$M$38))*(CP$5<>CO$5)) -> 1583.4626 | CQ19: =CP19*(1+INDEX(Assumptions!$C$43:$M$43,MATCH('DCF Model'!CQ5,Assumptions!$C$38:$M$38))*(CQ$5<>CP$5)) -> 1583.4626 | CR19: =CQ19*(1+INDEX(Assumptions!$C$43:$M$43,MATCH('DCF Model'!CR5,Assumptions!$C$38:$M$38))*(CR$5<>CQ$5)) -> 1583.4626 | CS19: =CR19*(1+INDEX(Assumptions!$C$43:$M$43,MATCH('DCF Model'!CS5,Assumptions!$C$38:$M$38))*(CS$5<>CR$5)) -> 1583.4626 | CT19: =CS19*(1+INDEX(Assumptions!$C$43:$M$43,MATCH('DCF Model'!CT5,Assumptions!$C$38:$M$38))*(CT$5<>CS$5)) -> 1583.4626 | ... CX19: =CW19*(1+INDEX(Assumptions!$C$43:$M$43,MATCH('DCF Model'!CX5,Assumptions!$C$38:$M$38))*(CX$5<>CW$5)) -> 1583.4626
B20: Loss to Lease | D20: =Assumptions!L18 -> -15000 | G20: =-INDEX(Assumptions!$C$40:$M$40,MATCH('DCF Model'!G5,Assumptions!$C$38:$M$38))*G16 -> -2812.5 | H20: =-INDEX(Assumptions!$C$40:$M$40,MATCH('DCF Model'!H5,Assumptions!$C$38:$M$38))*H16 -> -2812.5 | I20: =-INDEX(Assumptions!$C$40:$M$40,MATCH('DCF Model'!I5,Assumptions!$C$38:$M$38))*I16 -> -2812.5 | J20: =-INDEX(Assumptions!$C$40:$M$40,MATCH('DCF Model'!J5,Assumptions!$C$38:$M$38))*J16 -> -2812.5 | K20: =-INDEX(Assumptions!$C$40:$M$40,MATCH('DCF Model'!K5,Assumptions!$C$38:$M$38))*K16 -> -2812.5 | L20: =-INDEX(Assumptions!$C$40:$M$40,MATCH('DCF Model'!L5,Assumptions!$C$38:$M$38))*L16 -> -2812.5 | M20: =-INDEX(Assumptions!$C$40:$M$40,MATCH('DCF Model'!M5,Assumptions!$C$38:$M$38))*M16 -> -2812.5 | N20: =-INDEX(Assumptions!$C$40:$M$40,MATCH('DCF Model'!N5,Assumptions!$C$38:$M$38))*N16 -> -2812.5 | ... CX20: =-INDEX(Assumptions!$C$40:$M$40,MATCH('DCF Model'!CX5,Assumptions!$C$38:$M$38))*CX16 -> -4747.2273
B21: Total Gross Revenue | D21: =SUM(D16:D20) -> 4418750 | G21: =SUM(G16:G20) -> 391704.17 | H21: =SUM(H16:H20) -> 391704.17 | I21: =SUM(I16:I20) -> 391704.17 | J21: =SUM(J16:J20) -> 391704.17 | K21: =SUM(K16:K20) -> 391704.17 | L21: =SUM(L16:L20) -> 391704.17 | M21: =SUM(M16:M20) -> 391704.17 | N21: =SUM(N16:N20) -> 391704.17 | ... CX21: =SUM(CX16:CX20) -> 494260.21
B22: Residential Vacancy Loss | D22: =Assumptions!L24 -> -800000 | G22: =-INDEX(Assumptions!$C$44:$M$44,MATCH('DCF Model'!G5,Assumptions!$C$38:$M$38))*G16 -> -75000 | H22: =-INDEX(Assumptions!$C$44:$M$44,MATCH('DCF Model'!H5,Assumptions!$C$38:$M$38))*H16 -> -75000 | I22: =-INDEX(Assumptions!$C$44:$M$44,MATCH('DCF Model'!I5,Assumptions!$C$38:$M$38))*I16 -> -75000 | J22: =-INDEX(Assumptions!$C$44:$M$44,MATCH('DCF Model'!J5,Assumptions!$C$38:$M$38))*J16 -> -75000 | K22: =-INDEX(Assumptions!$C$44:$M$44,MATCH('DCF Model'!K5,Assumptions!$C$38:$M$38))*K16 -> -75000 | L22: =-INDEX(Assumptions!$C$44:$M$44,MATCH('DCF Model'!L5,Assumptions!$C$38:$M$38))*L16 -> -75000 | M22: =-INDEX(Assumptions!$C$44:$M$44,MATCH('DCF Model'!M5,Assumptions!$C$38:$M$38))*M16 -> -75000 | N22: =-INDEX(Assumptions!$C$44:$M$44,MATCH('DCF Model'!N5,Assumptions!$C$38:$M$38))*N16 -> -75000 | ... CX22: =-INDEX(Assumptions!$C$44:$M$44,MATCH('DCF Model'!CX5,Assumptions!$C$38:$M$38))*CX16 -> -23736.137
B23: Commercial Vacancy Loss | D23: =Assumptions!L20 -> -9375 | G23: =-INDEX(Assumptions!$C$42:$M$42,MATCH('DCF Model'!G5,Assumptions!$C$38:$M$38))*G17 -> -781.25 | H23: =-INDEX(Assumptions!$C$42:$M$42,MATCH('DCF Model'!H5,Assumptions!$C$38:$M$38))*H17 -> -781.25 | I23: =-INDEX(Assumptions!$C$42:$M$42,MATCH('DCF Model'!I5,Assumptions!$C$38:$M$38))*I17 -> -781.25 | J23: =-INDEX(Assumptions!$C$42:$M$42,MATCH('DCF Model'!J5,Assumptions!$C$38:$M$38))*J17 -> -781.25 | K23: =-INDEX(Assumptions!$C$42:$M$42,MATCH('DCF Model'!K5,Assumptions!$C$38:$M$38))*K17 -> -781.25 | L23: =-INDEX(Assumptions!$C$42:$M$42,MATCH('DCF Model'!L5,Assumptions!$C$38:$M$38))*L17 -> -781.25 | M23: =-INDEX(Assumptions!$C$42:$M$42,MATCH('DCF Model'!M5,Assumptions!$C$38:$M$38))*M17 -> -781.25 | N23: =-INDEX(Assumptions!$C$42:$M$42,MATCH('DCF Model'!N5,Assumptions!$C$38:$M$38))*N17 -> -781.25 | ... CX23: =-INDEX(Assumptions!$C$42:$M$42,MATCH('DCF Model'!CX5,Assumptions!$C$38:$M$38))*CX17 -> -989.00569
B24: Concessions | D24: =Assumptions!L25 -> -400000 | G24: =-INDEX(Assumptions!$C$45:$M$45,MATCH('DCF Model'!G5,Assumptions!$C$38:$M$38))*(G16+G17) -> -38281.25 | H24: =-INDEX(Assumptions!$C$45:$M$45,MATCH('DCF Model'!H5,Assumptions!$C$38:$M$38))*(H16+H17) -> -38281.25 | I24: =-INDEX(Assumptions!$C$45:$M$45,MATCH('DCF Model'!I5,Assumptions!$C$38:$M$38))*(I16+I17) -> -38281.25 | J24: =-INDEX(Assumptions!$C$45:$M$45,MATCH('DCF Model'!J5,Assumptions!$C$38:$M$38))*(J16+J17) -> -38281.25 | K24: =-INDEX(Assumptions!$C$45:$M$45,MATCH('DCF Model'!K5,Assumptions!$C$38:$M$38))*(K16+K17) -> -38281.25 | L24: =-INDEX(Assumptions!$C$45:$M$45,MATCH('DCF Model'!L5,Assumptions!$C$38:$M$38))*(L16+L17) -> -38281.25 | M24: =-INDEX(Assumptions!$C$45:$M$45,MATCH('DCF Model'!M5,Assumptions!$C$38:$M$38))*(M16+M17) -> -38281.25 | N24: =-INDEX(Assumptions!$C$45:$M$45,MATCH('DCF Model'!N5,Assumptions!$C$38:$M$38))*(N16+N17) -> -38281.25 | ... CX24: =-INDEX(Assumptions!$C$45:$M$45,MATCH('DCF Model'!CX5,Assumptions!$C$38:$M$38))*(CX16+CX17) -> -9692.2558
B25: Bad Debt / Non. Rev Units (considered Residential & Commercial) | D25: =Assumptions!L26 -> -110485 | G25: =-INDEX(Assumptions!$C$47:$M$47,MATCH('DCF Model'!G5,Assumptions!$C$38:$M$38))*(G$16+G$17) -> -7656.25 | H25: =-INDEX(Assumptions!$C$47:$M$47,MATCH('DCF Model'!H5,Assumptions!$C$38:$M$38))*(H$16+H$17) -> -7656.25 | I25: =-INDEX(Assumptions!$C$47:$M$47,MATCH('DCF Model'!I5,Assumptions!$C$38:$M$38))*(I$16+I$17) -> -7656.25 | J25: =-INDEX(Assumptions!$C$47:$M$47,MATCH('DCF Model'!J5,Assumptions!$C$38:$M$38))*(J$16+J$17) -> -7656.25 | K25: =-INDEX(Assumptions!$C$47:$M$47,MATCH('DCF Model'!K5,Assumptions!$C$38:$M$38))*(K$16+K$17) -> -7656.25 | L25: =-INDEX(Assumptions!$C$47:$M$47,MATCH('DCF Model'!L5,Assumptions!$C$38:$M$38))*(L$16+L$17) -> -7656.25 | M25: =-INDEX(Assumptions!$C$47:$M$47,MATCH('DCF Model'!M5,Assumptions!$C$38:$M$38))*(M$16+M$17) -> -7656.25 | N25: =-INDEX(Assumptions!$C$47:$M$47,MATCH('DCF Model'!N5,Assumptions!$C$38:$M$38))*(N$16+N$17) -> -7656.25 | ... CX25: =-INDEX(Assumptions!$C$47:$M$47,MATCH('DCF Model'!CX5,Assumptions!$C$38:$M$38))*(CX$16+CX$17) -> -9692.2558
B26: Effective Gross Revenue | D26: =SUM(D21:D25) -> 3098890 | G26: =SUM(G21:G25) -> 269985.42 | H26: =SUM(H21:H25) -> 269985.42 | I26: =SUM(I21:I25) -> 269985.42 | J26: =SUM(J21:J25) -> 269985.42 | K26: =SUM(K21:K25) -> 269985.42 | L26: =SUM(L21:L25) -> 269985.42 | M26: =SUM(M21:M25) -> 269985.42 | N26: =SUM(N21:N25) -> 269985.42 | ... CX26: =SUM(CX21:CX25) -> 450150.56
B28: Residential Effective Rent / Month | D28: =SUM(D16:D23)/D5/12 -> 2230.0347 | G28: =SUM(G16:G23)/$D$5 -> 2358.7569 | H28: =SUM(H16:H23)/$D$5 -> 2358.7569 | I28: =SUM(I16:I23)/$D$5 -> 2358.7569 | J28: =SUM(J16:J23)/$D$5 -> 2358.7569 | K28: =SUM(K16:K23)/$D$5 -> 2358.7569 | L28: =SUM(L16:L23)/$D$5 -> 2358.7569 | M28: =SUM(M16:M23)/$D$5 -> 2358.7569 | N28: =SUM(N16:N23)/$D$5 -> 2358.7569 | ... CX28: =SUM(CX16:CX23)/$D$5 -> 3212.6509
B29: Commercial Effective Rent PSF / Month | D29: =SUM(D17:D23)/D6/12 -> 85.069444 | G29: =SUM(G17:G23)/$D$6 -> 88.700556 | H29: =SUM(H17:H23)/$D$6 -> 88.700556 | I29: =SUM(I17:I23)/$D$6 -> 88.700556 | J29: =SUM(J17:J23)/$D$6 -> 88.700556 | K29: =SUM(K17:K23)/$D$6 -> 88.700556 | L29: =SUM(L17:L23)/$D$6 -> 88.700556 | M29: =SUM(M17:M23)/$D$6 -> 88.700556 | N29: =SUM(N17:N23)/$D$6 -> 88.700556 | ... CX29: =SUM(CX17:CX23)/$D$6 -> 130.41935
B30: Residential Physical Occupancy | D30: =D22/D16+1 -> 0.80952381 | G30: =1-INDEX(Assumptions!$C$44:$M$44,MATCH('DCF Model'!G5,Assumptions!$C$38:$M$38)) -> 0.8 | H30: =1-INDEX(Assumptions!$C$44:$M$44,MATCH('DCF Model'!H5,Assumptions!$C$38:$M$38)) -> 0.8 | I30: =1-INDEX(Assumptions!$C$44:$M$44,MATCH('DCF Model'!I5,Assumptions!$C$38:$M$38)) -> 0.8 | J30: =1-INDEX(Assumptions!$C$44:$M$44,MATCH('DCF Model'!J5,Assumptions!$C$38:$M$38)) -> 0.8 | K30: =1-INDEX(Assumptions!$C$44:$M$44,MATCH('DCF Model'!K5,Assumptions!$C$38:$M$38)) -> 0.8 | L30: =1-INDEX(Assumptions!$C$44:$M$44,MATCH('DCF Model'!L5,Assumptions!$C$38:$M$38)) -> 0.8 | M30: =1-INDEX(Assumptions!$C$44:$M$44,MATCH('DCF Model'!M5,Assumptions!$C$38:$M$38)) -> 0.8 | N30: =1-INDEX(Assumptions!$C$44:$M$44,MATCH('DCF Model'!N5,Assumptions!$C$38:$M$38)) -> 0.8 | ... CX30: =1-INDEX(Assumptions!$C$44:$M$44,MATCH('DCF Model'!CX5,Assumptions!$C$38:$M$38)) -> 0.95
B31: Residential Economic Occupancy | D31: =(D16+D22)/D16 -> 0.80952381 | G31: =(G16+G22)/G16 -> 0.8 | H31: =(H16+H22)/H16 -> 0.8 | I31: =(I16+I22)/I16 -> 0.8 | J31: =(J16+J22)/J16 -> 0.8 | K31: =(K16+K22)/K16 -> 0.8 | L31: =(L16+L22)/L16 -> 0.8 | M31: =(M16+M22)/M16 -> 0.8 | N31: =(N16+N22)/N16 -> 0.8 | ... CX31: =(CX16+CX22)/CX16 -> 0.95
B32: Commercial Physical Occupancy | D32: =D23/D17+1 -> 0.9 | G32: =1-INDEX(Assumptions!$C$42:$M$42,MATCH('DCF Model'!G5,Assumptions!$C$38:$M$38)) -> 0.9 | H32: =1-INDEX(Assumptions!$C$42:$M$42,MATCH('DCF Model'!H5,Assumptions!$C$38:$M$38)) -> 0.9 | I32: =1-INDEX(Assumptions!$C$42:$M$42,MATCH('DCF Model'!I5,Assumptions!$C$38:$M$38)) -> 0.9 | J32: =1-INDEX(Assumptions!$C$42:$M$42,MATCH('DCF Model'!J5,Assumptions!$C$38:$M$38)) -> 0.9 | K32: =1-INDEX(Assumptions!$C$42:$M$42,MATCH('DCF Model'!K5,Assumptions!$C$38:$M$38)) -> 0.9 | L32: =1-INDEX(Assumptions!$C$42:$M$42,MATCH('DCF Model'!L5,Assumptions!$C$38:$M$38)) -> 0.9 | M32: =1-INDEX(Assumptions!$C$42:$M$42,MATCH('DCF Model'!M5,Assumptions!$C$38:$M$38)) -> 0.9 | N32: =1-INDEX(Assumptions!$C$42:$M$42,MATCH('DCF Model'!N5,Assumptions!$C$38:$M$38)) -> 0.9 | ... CX32: =1-INDEX(Assumptions!$C$42:$M$42,MATCH('DCF Model'!CX5,Assumptions!$C$38:$M$38)) -> 0.9
B33: Commercial Economic Occupancy | D33: =(D17+D23)/D17 -> 0.9 | G33: =(G17+G23)/G17 -> 0.9 | H33: =(H17+H23)/H17 -> 0.9 | I33: =(I17+I23)/I17 -> 0.9 | J33: =(J17+J23)/J17 -> 0.9 | K33: =(K17+K23)/K17 -> 0.9 | L33: =(L17+L23)/L17 -> 0.9 | M33: =(M17+M23)/M17 -> 0.9 | N33: =(N17+N23)/N17 -> 0.9 | ... CX33: =(CX17+CX23)/CX17 -> 0.9
B35: OPERATING EXPENSES
B36: Real Estate Taxes | D36: =Assumptions!L28 -> -799318 | G36: =(1+INDEX(Assumptions!$C$48:$M$48,MATCH('DCF Model'!G5,Assumptions!$C$38:$M$38))*(G$5<>F$5))*D36/12 -> -68608.128 | H36: =(1+INDEX(Assumptions!$C$48:$M$48,MATCH('DCF Model'!H5,Assumptions!$C$38:$M$38))*(H$5<>G$5))*G36 -> -68608.128 | I36: =(1+INDEX(Assumptions!$C$48:$M$48,MATCH('DCF Model'!I5,Assumptions!$C$38:$M$38))*(I$5<>H$5))*H36 -> -68608.128 | J36: =(1+INDEX(Assumptions!$C$48:$M$48,MATCH('DCF Model'!J5,Assumptions!$C$38:$M$38))*(J$5<>I$5))*I36 -> -68608.128 | K36: =(1+INDEX(Assumptions!$C$48:$M$48,MATCH('DCF Model'!K5,Assumptions!$C$38:$M$38))*(K$5<>J$5))*J36 -> -68608.128 | L36: =(1+INDEX(Assumptions!$C$48:$M$48,MATCH('DCF Model'!L5,Assumptions!$C$38:$M$38))*(L$5<>K$5))*K36 -> -68608.128 | M36: =(1+INDEX(Assumptions!$C$48:$M$48,MATCH('DCF Model'!M5,Assumptions!$C$38:$M$38))*(M$5<>L$5))*L36 -> -68608.128 | N36: =(1+INDEX(Assumptions!$C$48:$M$48,MATCH('DCF Model'!N5,Assumptions!$C$38:$M$38))*(N$5<>M$5))*M36 -> -68608.128 | O36: =(1+INDEX(Assumptions!$C$48:$M$48,MATCH('DCF Model'!O5,Assumptions!$C$38:$M$38))*(O$5<>N$5))*N36 -> -68608.128 | ... CX36: =(1+INDEX(Assumptions!$C$48:$M$48,MATCH('DCF Model'!CX5,Assumptions!$C$38:$M$38))*(CX$5<>CW$5))*CW36 -> -84379.344
B37: Insurance | D37: =Assumptions!L29 -> -125785 | G37: =(1+INDEX(Assumptions!$C$49:$M$49,MATCH('DCF Model'!G5,Assumptions!$C$38:$M$38))*(G$5<>F$5))*D37/12 -> -10796.546 | H37: =(1+INDEX(Assumptions!$C$49:$M$49,MATCH('DCF Model'!H5,Assumptions!$C$38:$M$38))*(H$5<>G$5))*G37 -> -10796.546 | I37: =(1+INDEX(Assumptions!$C$49:$M$49,MATCH('DCF Model'!I5,Assumptions!$C$38:$M$38))*(I$5<>H$5))*H37 -> -10796.546 | J37: =(1+INDEX(Assumptions!$C$49:$M$49,MATCH('DCF Model'!J5,Assumptions!$C$38:$M$38))*(J$5<>I$5))*I37 -> -10796.546 | K37: =(1+INDEX(Assumptions!$C$49:$M$49,MATCH('DCF Model'!K5,Assumptions!$C$38:$M$38))*(K$5<>J$5))*J37 -> -10796.546 | L37: =(1+INDEX(Assumptions!$C$49:$M$49,MATCH('DCF Model'!L5,Assumptions!$C$38:$M$38))*(L$5<>K$5))*K37 -> -10796.546 | M37: =(1+INDEX(Assumptions!$C$49:$M$49,MATCH('DCF Model'!M5,Assumptions!$C$38:$M$38))*(M$5<>L$5))*L37 -> -10796.546 | N37: =(1+INDEX(Assumptions!$C$49:$M$49,MATCH('DCF Model'!N5,Assumptions!$C$38:$M$38))*(N$5<>M$5))*M37 -> -10796.546 | O37: =(1+INDEX(Assumptions!$C$49:$M$49,MATCH('DCF Model'!O5,Assumptions!$C$38:$M$38))*(O$5<>N$5))*N37 -> -10796.546 | ... CX37: =(1+INDEX(Assumptions!$C$49:$M$49,MATCH('DCF Model'!CX5,Assumptions!$C$38:$M$38))*(CX$5<>CW$5))*CW37 -> -13278.39
B38: Controllable Operating Expenses | D38: =Assumptions!L31 -> -927010 | G38: =(1+INDEX(Assumptions!$C$50:$M$50,MATCH('DCF Model'!G5,Assumptions!$C$38:$M$38))*(G$5<>F$5))*D38/12 -> -79568.358 | H38: =(1+INDEX(Assumptions!$C$50:$M$50,MATCH('DCF Model'!H5,Assumptions!$C$38:$M$38))*(H$5<>G$5))*G38 -> -79568.358 | I38: =(1+INDEX(Assumptions!$C$50:$M$50,MATCH('DCF Model'!I5,Assumptions!$C$38:$M$38))*(I$5<>H$5))*H38 -> -79568.358 | J38: =(1+INDEX(Assumptions!$C$50:$M$50,MATCH('DCF Model'!J5,Assumptions!$C$38:$M$38))*(J$5<>I$5))*I38 -> -79568.358 | K38: =(1+INDEX(Assumptions!$C$50:$M$50,MATCH('DCF Model'!K5,Assumptions!$C$38:$M$38))*(K$5<>J$5))*J38 -> -79568.358 | L38: =(1+INDEX(Assumptions!$C$50:$M$50,MATCH('DCF Model'!L5,Assumptions!$C$38:$M$38))*(L$5<>K$5))*K38 -> -79568.358 | M38: =(1+INDEX(Assumptions!$C$50:$M$50,MATCH('DCF Model'!M5,Assumptions!$C$38:$M$38))*(M$5<>L$5))*L38 -> -79568.358 | N38: =(1+INDEX(Assumptions!$C$50:$M$50,MATCH('DCF Model'!N5,Assumptions!$C$38:$M$38))*(N$5<>M$5))*M38 -> -79568.358 | O38: =(1+INDEX(Assumptions!$C$50:$M$50,MATCH('DCF Model'!O5,Assumptions!$C$38:$M$38))*(O$5<>N$5))*N38 -> -79568.358 | ... CX38: =(1+INDEX(Assumptions!$C$50:$M$50,MATCH('DCF Model'!CX5,Assumptions!$C$38:$M$38))*(CX$5<>CW$5))*CW38 -> -97859.044
B39: Management Fee (% of total revenue) | D39: =Assumptions!L30 -> -122556 | G39: =-INDEX(Assumptions!$C$51:$M$51,MATCH('DCF Model'!G5,Assumptions!$C$38:$M$38))*G26 -> -8099.5625 | H39: =-INDEX(Assumptions!$C$51:$M$51,MATCH('DCF Model'!H5,Assumptions!$C$38:$M$38))*H26 -> -8099.5625 | I39: =-INDEX(Assumptions!$C$51:$M$51,MATCH('DCF Model'!I5,Assumptions!$C$38:$M$38))*I26 -> -8099.5625 | J39: =-INDEX(Assumptions!$C$51:$M$51,MATCH('DCF Model'!J5,Assumptions!$C$38:$M$38))*J26 -> -8099.5625 | K39: =-INDEX(Assumptions!$C$51:$M$51,MATCH('DCF Model'!K5,Assumptions!$C$38:$M$38))*K26 -> -8099.5625 | L39: =-INDEX(Assumptions!$C$51:$M$51,MATCH('DCF Model'!L5,Assumptions!$C$38:$M$38))*L26 -> -8099.5625 | M39: =-INDEX(Assumptions!$C$51:$M$51,MATCH('DCF Model'!M5,Assumptions!$C$38:$M$38))*M26 -> -8099.5625 | N39: =-INDEX(Assumptions!$C$51:$M$51,MATCH('DCF Model'!N5,Assumptions!$C$38:$M$38))*N26 -> -8099.5625 | ... CX39: =-INDEX(Assumptions!$C$51:$M$51,MATCH('DCF Model'!CX5,Assumptions!$C$38:$M$38))*CX26 -> -13504.517
B40: Total Operating Expenses | D40: =SUM(D36:D39) -> -1974669 | G40: =SUM(G36:G39) -> -167072.6 | H40: =SUM(H36:H39) -> -167072.6 | I40: =SUM(I36:I39) -> -167072.6 | J40: =SUM(J36:J39) -> -167072.6 | K40: =SUM(K36:K39) -> -167072.6 | L40: =SUM(L36:L39) -> -167072.6 | M40: =SUM(M36:M39) -> -167072.6 | N40: =SUM(N36:N39) -> -167072.6 | ... CX40: =SUM(CX36:CX39) -> -209021.29
B42: Capex Reserve | D42: =Assumptions!L33 -> -45000 | G42: =-INDEX(Assumptions!$C$52:$M$52,MATCH('DCF Model'!G5,Assumptions!$C$38:$M$38))*(G$5>1)*$D$5/12 -> 0 | H42: =-INDEX(Assumptions!$C$52:$M$52,MATCH('DCF Model'!H5,Assumptions!$C$38:$M$38))*(H$5>1)*$D$5/12 -> 0 | I42: =-INDEX(Assumptions!$C$52:$M$52,MATCH('DCF Model'!I5,Assumptions!$C$38:$M$38))*(I$5>1)*$D$5/12 -> 0 | J42: =-INDEX(Assumptions!$C$52:$M$52,MATCH('DCF Model'!J5,Assumptions!$C$38:$M$38))*(J$5>1)*$D$5/12 -> 0 | K42: =-INDEX(Assumptions!$C$52:$M$52,MATCH('DCF Model'!K5,Assumptions!$C$38:$M$38))*(K$5>1)*$D$5/12 -> 0 | L42: =-INDEX(Assumptions!$C$52:$M$52,MATCH('DCF Model'!L5,Assumptions!$C$38:$M$38))*(L$5>1)*$D$5/12 -> 0 | M42: =-INDEX(Assumptions!$C$52:$M$52,MATCH('DCF Model'!M5,Assumptions!$C$38:$M$38))*(M$5>1)*$D$5/12 -> 0 | N42: =-INDEX(Assumptions!$C$52:$M$52,MATCH('DCF Model'!N5,Assumptions!$C$38:$M$38))*(N$5>1)*$D$5/12 -> 0 | ... R42: =-INDEX(Assumptions!$C$52:$M$52,MATCH('DCF Model'!R5,Assumptions!$C$38:$M$38))*(R$5>1)*$D$5/12 -> 0 | S42: =-INDEX(Assumptions!$C$52:$M$52,MATCH('DCF Model'!G5,Assumptions!$C$38:$M$38))*(S$5>1)*$D$5/12 -> -5000 | T42: =-INDEX(Assumptions!$C$52:$M$52,MATCH('DCF Model'!H5,Assumptions!$C$38:$M$38))*(T$5>1)*$D$5/12 -> -5000 | U42: =-INDEX(Assumptions!$C$52:$M$52,MATCH('DCF Model'!I5,Assumptions!$C$38:$M$38))*(U$5>1)*$D$5/12 -> -5000 | V42: =-INDEX(Assumptions!$C$52:$M$52,MATCH('DCF Model'!J5,Assumptions!$C$38:$M$38))*(V$5>1)*$D$5/12 -> -5000 | W42: =-INDEX(Assumptions!$C$52:$M$52,MATCH('DCF Model'!K5,Assumptions!$C$38:$M$38))*(W$5>1)*$D$5/12 -> -5000 | X42: =-INDEX(Assumptions!$C$52:$M$52,MATCH('DCF Model'!L5,Assumptions!$C$38:$M$38))*(X$5>1)*$D$5/12 -> -5000 | Y42: =-INDEX(Assumptions!$C$52:$M$52,MATCH('DCF Model'!M5,Assumptions!$C$38:$M$38))*(Y$5>1)*$D$5/12 -> -5000 | Z42: =-INDEX(Assumptions!$C$52:$M$52,MATCH('DCF Model'!N5,Assumptions!$C$38:$M$38))*(Z$5>1)*$D$5/12 -> -5000 | ... CX42: =-INDEX(Assumptions!$C$52:$M$52,MATCH('DCF Model'!CL5,Assumptions!$C$38:$M$38))*(CX$5>1)*$D$5/12 -> -5625
B43: NET OPERATING INCOME | D43: =D26+D40+D42 -> 1079221 | G43: =G26+G40+G42 -> 102912.82 | H43: =H26+H40+H42 -> 102912.82 | I43: =I26+I40+I42 -> 102912.82 | J43: =J26+J40+J42 -> 102912.82 | K43: =K26+K40+K42 -> 102912.82 | L43: =L26+L40+L42 -> 102912.82 | M43: =M26+M40+M42 -> 102912.82 | N43: =N26+N40+N42 -> 102912.82 | ... CX43: =CX26+CX40+CX42 -> 235504.26
B45: Capital Improvements | D45: =Assumptions!L35 -> -35000 | G45: =-INDEX(Assumptions!$C$53:$M$53,MATCH('DCF Model'!G5,Assumptions!$C$38:$M$38))*(G$5<>F$5) -> -50000 | H45: =-INDEX(Assumptions!$C$53:$M$53,MATCH('DCF Model'!H5,Assumptions!$C$38:$M$38))*(H$5<>G$5) -> 0 | I45: =-INDEX(Assumptions!$C$53:$M$53,MATCH('DCF Model'!I5,Assumptions!$C$38:$M$38))*(I$5<>H$5) -> 0 | J45: =-INDEX(Assumptions!$C$53:$M$53,MATCH('DCF Model'!J5,Assumptions!$C$38:$M$38))*(J$5<>I$5) -> 0 | K45: =-INDEX(Assumptions!$C$53:$M$53,MATCH('DCF Model'!K5,Assumptions!$C$38:$M$38))*(K$5<>J$5) -> 0 | L45: =-INDEX(Assumptions!$C$53:$M$53,MATCH('DCF Model'!L5,Assumptions!$C$38:$M$38))*(L$5<>K$5) -> 0 | M45: =-INDEX(Assumptions!$C$53:$M$53,MATCH('DCF Model'!M5,Assumptions!$C$38:$M$38))*(M$5<>L$5) -> 0 | N45: =-INDEX(Assumptions!$C$53:$M$53,MATCH('DCF Model'!N5,Assumptions!$C$38:$M$38))*(N$5<>M$5) -> 0 | ... CL45: =-INDEX(Assumptions!$C$53:$M$53,MATCH('DCF Model'!CL5,Assumptions!$C$38:$M$38))*(CL$5<>CK$5) -> 0 | CM45: =-INDEX(Assumptions!$C$53:$M$53,MATCH('DCF Model'!CM5,Assumptions!$C$38:$M$38))/12 -> 0 | CN45: =-INDEX(Assumptions!$C$53:$M$53,MATCH('DCF Model'!CN5,Assumptions!$C$38:$M$38))/12 -> 0 | CO45: =-INDEX(Assumptions!$C$53:$M$53,MATCH('DCF Model'!CO5,Assumptions!$C$38:$M$38))/12 -> 0 | CP45: =-INDEX(Assumptions!$C$53:$M$53,MATCH('DCF Model'!CP5,Assumptions!$C$38:$M$38))/12 -> 0 | CQ45: =-INDEX(Assumptions!$C$53:$M$53,MATCH('DCF Model'!CQ5,Assumptions!$C$38:$M$38))/12 -> 0 | CR45: =-INDEX(Assumptions!$C$53:$M$53,MATCH('DCF Model'!CR5,Assumptions!$C$38:$M$38))/12 -> 0 | CS45: =-INDEX(Assumptions!$C$53:$M$53,MATCH('DCF Model'!CS5,Assumptions!$C$38:$M$38))/12 -> 0 | CT45: =-INDEX(Assumptions!$C$53:$M$53,MATCH('DCF Model'!CT5,Assumptions!$C$38:$M$38))/12 -> 0 | ... CX45: =-INDEX(Assumptions!$C$53:$M$53,MATCH('DCF Model'!CX5,Assumptions!$C$38:$M$38))/12 -> 0
B46: COMBINED NET CASH FLOW | D46: =D43+D45 -> 1044221 | G46: =G43+G45 -> 52912.822 | H46: =H43+H45 -> 102912.82 | I46: =I43+I45 -> 102912.82 | J46: =J43+J45 -> 102912.82 | K46: =K43+K45 -> 102912.82 | L46: =L43+L45 -> 102912.82 | M46: =M43+M45 -> 102912.82 | N46: =N43+N45 -> 102912.82 | ... CX46: =CX43+CX45 -> 235504.26
B48: Forward 12 Month NOI | G48: =IF(G5<=Assumptions!$B$35,SUM('DCF Model'!H43:S43),0) -> 1275688.7 | H48: =IF(H5<=Assumptions!$B$35,SUM('DCF Model'!I43:T43),0) -> 1316423.5 | I48: =IF(I5<=Assumptions!$B$35,SUM('DCF Model'!J43:U43),0) -> 1357158.3 | J48: =IF(J5<=Assumptions!$B$35,SUM('DCF Model'!K43:V43),0) -> 1397893.1 | K48: =IF(K5<=Assumptions!$B$35,SUM('DCF Model'!L43:W43),0) -> 1438627.9 | L48: =IF(L5<=Assumptions!$B$35,SUM('DCF Model'!M43:X43),0) -> 1479362.7 | M48: =IF(M5<=Assumptions!$B$35,SUM('DCF Model'!N43:Y43),0) -> 1520097.5 | N48: =IF(N5<=Assumptions!$B$35,SUM('DCF Model'!O43:Z43),0) -> 1560832.2 | ... CL48: =IF(CL5<=Assumptions!$B$35,SUM('DCF Model'!CM43:CX43),0) -> 2826051.2
...

Sheet Annual Summary
B2: Annual Summary
B3: Acquisition Date | D3: =Assumptions!B31 -> 46023
B4: Exit Date | D4: 48579
B5: Units | D5: =Assumptions!B23 -> 300
B6: Commercial SqFt | D6: =Assumptions!B24 -> 3750
F7: 0 | G7: =$F$7+1 -> 1 | H7: =G7+1 -> 2 | I7: =H7+1 -> 3 | J7: =I7+1 -> 4 | K7: =J7+1 -> 5 | L7: =K7+1 -> 6 | M7: =L7+1 -> 7 | N7: =M7+1 -> 8
F8: ='DCF Model'!F7 -> 46023 | G8: ='DCF Model'!R7 -> 46387 | H8: ='DCF Model'!AD7 -> 46752 | I8: ='DCF Model'!AP7 -> 47118 | J8: ='DCF Model'!BB7 -> 47483 | K8: ='DCF Model'!BN7 -> 47848 | L8: ='DCF Model'!BZ7 -> 48213 | M8: ='DCF Model'!CL7 -> 48579 | N8: ='DCF Model'!CX7 -> 48944
B9: INCOME
B10: Residential Gross Potential Rent (GPR) | D10: =Assumptions!L17 -> 4200000 | G10: =SUM('DCF Model'!G16:R16) -> 4500000 | H10: =SUM('DCF Model'!S16:AD16) -> 4725000 | I10: =SUM('DCF Model'!AE16:AP16) -> 4914000 | J10: =SUM('DCF Model'!AQ16:BB16) -> 5061420 | K10: =SUM('DCF Model'!BC16:BN16) -> 5213262.6 | L10: =SUM('DCF Model'!BO16:BZ16) -> 5369660.5 | M10: =SUM('DCF Model'!CA16:CL16) -> 5530750.3 | N10: =SUM('DCF Model'!CM16:CX16) -> 5696672.8
B11: Commercial Effective Rent | D11: =Assumptions!L19 -> 93750 | G11: =SUM('DCF Model'!G17:R17) -> 93750 | H11: =SUM('DCF Model'!S17:AD17) -> 98437.5 | I11: =SUM('DCF Model'!AE17:AP17) -> 102375 | J11: =SUM('DCF Model'!AQ17:BB17) -> 105446.25 | K11: =SUM('DCF Model'!BC17:BN17) -> 108609.64 | L11: =SUM('DCF Model'!BO17:BZ17) -> 111867.93 | M11: =SUM('DCF Model'!CA17:CL17) -> 115223.96 | N11: =SUM('DCF Model'!CM17:CX17) -> 118680.68
B12: Other Income (Yr) | D12: =Assumptions!L22 -> 125000 | G12: =SUM('DCF Model'!G18:R18) -> 125000 | H12: =SUM('DCF Model'!S18:AD18) -> 128750 | I12: =SUM('DCF Model'!AE18:AP18) -> 132612.5 | J12: =SUM('DCF Model'!AQ18:BB18) -> 136590.88 | K12: =SUM('DCF Model'!BC18:BN18) -> 140688.6 | L12: =SUM('DCF Model'!BO18:BZ18) -> 144909.26 | M12: =SUM('DCF Model'!CA18:CL18) -> 149256.54 | N12: =SUM('DCF Model'!CM18:CX18) -> 153734.23
B13: CAM (Yr) | D13: =Assumptions!L21 -> 15000 | G13: =SUM('DCF Model'!G19:R19) -> 15450 | H13: =SUM('DCF Model'!S19:AD19) -> 15913.5 | I13: =SUM('DCF Model'!AE19:AP19) -> 16390.905 | J13: =SUM('DCF Model'!AQ19:BB19) -> 16882.632 | K13: =SUM('DCF Model'!BC19:BN19) -> 17389.111 | L13: =SUM('DCF Model'!BO19:BZ19) -> 17910.784 | M13: =SUM('DCF Model'!CA19:CL19) -> 18448.108 | N13: =SUM('DCF Model'!CM19:CX19) -> 19001.551
B14: Loss to Lease | D14: =Assumptions!L18 -> -15000 | G14: =SUM('DCF Model'!G20:R20) -> -33750 | H14: =SUM('DCF Model'!S20:AD20) -> -47250 | I14: =SUM('DCF Model'!AE20:AP20) -> -49140 | J14: =SUM('DCF Model'!AQ20:BB20) -> -50614.2 | K14: =SUM('DCF Model'!BC20:BN20) -> -52132.626 | L14: =SUM('DCF Model'!BO20:BZ20) -> -53696.605 | M14: =SUM('DCF Model'!CA20:CL20) -> -55307.503 | N14: =SUM('DCF Model'!CM20:CX20) -> -56966.728
B15: Total Gross Revenue | D15: =SUM(D10:D14) -> 4418750 | G15: =SUM(G10:G14) -> 4700450 | H15: =SUM(H10:H14) -> 4920851 | I15: =SUM(I10:I14) -> 5116238.4 | J15: =SUM(J10:J14) -> 5269725.6 | K15: =SUM(K10:K14) -> 5427817.3 | L15: =SUM(L10:L14) -> 5590651.8 | M15: =SUM(M10:M14) -> 5758371.4 | N15: =SUM(N10:N14) -> 5931122.5
B16: Residential Vacancy Loss | D16: =Assumptions!L24 -> -800000 | G16: =SUM('DCF Model'!G22:R22) -> -900000 | H16: =SUM('DCF Model'!S22:AD22) -> -708750 | I16: =SUM('DCF Model'!AE22:AP22) -> -245700 | J16: =SUM('DCF Model'!AQ22:BB22) -> -253071 | K16: =SUM('DCF Model'!BC22:BN22) -> -260663.13 | L16: =SUM('DCF Model'!BO22:BZ22) -> -268483.02 | M16: =SUM('DCF Model'!CA22:CL22) -> -276537.51 | N16: =SUM('DCF Model'!CM22:CX22) -> -284833.64
B17: Commercial Vacancy Loss | D17: =Assumptions!L20 -> -9375 | G17: =SUM('DCF Model'!G23:R23) -> -9375 | H17: =SUM('DCF Model'!S23:AD23) -> -9843.75 | I17: =SUM('DCF Model'!AE23:AP23) -> -10237.5 | J17: =SUM('DCF Model'!AQ23:BB23) -> -10544.625 | K17: =SUM('DCF Model'!BC23:BN23) -> -10860.964 | L17: =SUM('DCF Model'!BO23:BZ23) -> -11186.793 | M17: =SUM('DCF Model'!CA23:CL23) -> -11522.396 | N17: =SUM('DCF Model'!CM23:CX23) -> -11868.068
B18: Concessions | D18: =Assumptions!L25 -> -400000 | G18: =SUM('DCF Model'!G24:R24) -> -459375 | H18: =SUM('DCF Model'!S24:AD24) -> -241171.88 | I18: =SUM('DCF Model'!AE24:AP24) -> -175573.13 | J18: =SUM('DCF Model'!AQ24:BB24) -> -103337.33 | K18: =SUM('DCF Model'!BC24:BN24) -> -106437.44 | L18: =SUM('DCF Model'!BO24:BZ24) -> -109630.57 | M18: =SUM('DCF Model'!CA24:CL24) -> -112919.49 | N18: =SUM('DCF Model'!CM24:CX24) -> -116307.07
B19: Bad Debt / Non. Rev Units (considered Residential & Commercial) | D19: -110485 | G19: =SUM('DCF Model'!G25:R25) -> -91875 | H19: =SUM('DCF Model'!S25:AD25) -> -96468.75 | I19: =SUM('DCF Model'!AE25:AP25) -> -100327.5 | J19: =SUM('DCF Model'!AQ25:BB25) -> -103337.33 | K19: =SUM('DCF Model'!BC25:BN25) -> -106437.44 | L19: =SUM('DCF Model'!BO25:BZ25) -> -109630.57 | M19: =SUM('DCF Model'!CA25:CL25) -> -112919.49 | N19: =SUM('DCF Model'!CM25:CX25) -> -116307.07
B20: Effective Gross Revenue | D20: =SUM(D15:D19) -> 3098890 | G20: =SUM(G15:G19) -> 3239825 | H20: =SUM(H15:H19) -> 3864616.6 | I20: =SUM(I15:I19) -> 4584400.3 | J20: =SUM(J15:J19) -> 4799435.3 | K20: =SUM(K15:K19) -> 4943418.3 | L20: =SUM(L15:L19) -> 5091720.9 | M20: =SUM(M15:M19) -> 5244472.5 | N20: =SUM(N15:N19) -> 5401806.7
B22: OPERATING EXPENSES
B23: Real Estate Taxes | D23: =Assumptions!L28 -> -799318 | G23: =SUM('DCF Model'!G36:R36) -> -823297.54 | H23: =SUM('DCF Model'!S36:AD36) -> -847996.47 | I23: =SUM('DCF Model'!AE36:AP36) -> -873436.36 | J23: =SUM('DCF Model'!AQ36:BB36) -> -899639.45 | K23: =SUM('DCF Model'!BC36:BN36) -> -926628.63 | L23: =SUM('DCF Model'!BO36:BZ36) -> -954427.49 | M23: =SUM('DCF Model'!CA36:CL36) -> -983060.32 | N23: =SUM('DCF Model'!CM36:CX36) -> -1012552.1
B24: Insurance | D24: =Assumptions!L29 -> -125785 | G24: =SUM('DCF Model'!G37:R37) -> -129558.55 | H24: =SUM('DCF Model'!S37:AD37) -> -133445.31 | I24: =SUM('DCF Model'!AE37:AP37) -> -137448.67 | J24: =SUM('DCF Model'!AQ37:BB37) -> -141572.13 | K24: =SUM('DCF Model'!BC37:BN37) -> -145819.29 | L24: =SUM('DCF Model'!BO37:BZ37) -> -150193.87 | M24: =SUM('DCF Model'!CA37:CL37) -> -154699.68 | N24: =SUM('DCF Model'!CM37:CX37) -> -159340.67
B25: Controllable Operating Expenses | D25: =Assumptions!L31 -> -927010 | G25: =SUM('DCF Model'!G38:R38) -> -954820.3 | H25: =SUM('DCF Model'!S38:AD38) -> -983464.91 | I25: =SUM('DCF Model'!AE38:AP38) -> -1012968.9 | J25: =SUM('DCF Model'!AQ38:BB38) -> -1043357.9 | K25: =SUM('DCF Model'!BC38:BN38) -> -1074658.7 | L25: =SUM('DCF Model'!BO38:BZ38) -> -1106898.4 | M25: =SUM('DCF Model'!CA38:CL38) -> -1140105.4 | N25: =SUM('DCF Model'!CM38:CX38) -> -1174308.5
B26: Management Fee (% of total revenue) | D26: =Assumptions!L30 -> -122556 | G26: =SUM('DCF Model'!G39:R39) -> -97194.75 | H26: =SUM('DCF Model'!S39:AD39) -> -115938.5 | I26: =SUM('DCF Model'!AE39:AP39) -> -137532.01 | J26: =SUM('DCF Model'!AQ39:BB39) -> -143983.06 | K26: =SUM('DCF Model'!BC39:BN39) -> -148302.55 | L26: =SUM('DCF Model'!BO39:BZ39) -> -152751.63 | M26: =SUM('DCF Model'!CA39:CL39) -> -157334.18 | N26: =SUM('DCF Model'!CM39:CX39) -> -162054.2
B27: Total Operating Expenses | D27: =SUM(D23:D26) -> -1974669 | G27: =SUM(G23:G26) -> -2004871.1 | H27: =SUM(H23:H26) -> -2080845.2 | I27: =SUM(I23:I26) -> -2161385.9 | J27: =SUM(J23:J26) -> -2228552.6 | K27: =SUM(K23:K26) -> -2295409.1 | L27: =SUM(L23:L26) -> -2364271.4 | M27: =SUM(M23:M26) -> -2435199.6 | N27: =SUM(N23:N26) -> -2508255.5
B29: Capex Reserve | D29: =Assumptions!L33 -> -45000 | G29: =-INDEX(Assumptions!$C$52:$M$52,MATCH('Annual Summary'!G7,Assumptions!$C$38:$M$38))*(G$7>1)*$D$5 -> 0 | H29: =SUM('DCF Model'!S42:AD42) -> -60000 | I29: =SUM('DCF Model'!AE42:AP42) -> -61200 | J29: =SUM('DCF Model'!AQ42:BB42) -> -62400 | K29: =SUM('DCF Model'!BC42:BN42) -> -63600 | L29: =SUM('DCF Model'!BO42:BZ42) -> -64800 | M29: =SUM('DCF Model'!CA42:CL42) -> -66300 | N29: =SUM('DCF Model'!CM42:CX42) -> -67500
B30: NET OPERATING INCOME | D30: =D20+D27+D29 -> 1079221 | G30: =G20+G27+G29 -> 1234953.9 | H30: =H20+H27+H29 -> 1723771.4 | I30: =I20+I27+I29 -> 2361814.4 | J30: =J20+J27+J29 -> 2508482.7 | K30: =K20+K27+K29 -> 2584409.2 | L30: =L20+L27+L29 -> 2662649.5 | M30: =M20+M27+M29 -> 2742973 | N30: =N20+N27+N29 -> 2826051.2
B32: Capital Improvements | D32: =Assumptions!L35 -> -35000 | G32: =SUM('DCF Model'!G45:R45) -> -50000 | H32: =SUM('DCF Model'!S45:AD45) -> 0 | I32: =SUM('DCF Model'!AE45:AP45) -> 0 | J32: =SUM('DCF Model'!AQ45:BB45) -> 0 | K32: =SUM('DCF Model'!BC45:BN45) -> 0 | L32: =SUM('DCF Model'!BO45:BZ45) -> 0 | M32: =SUM('DCF Model'!CA45:CL45) -> 0 | N32: =SUM('DCF Model'!CB45:CM45) -> 0
B33: COMBINED NET CASH FLOW | D33: =D30+D32 -> 1044221 | G33: =G30+G32 -> 1184953.9 | H33: =H30+H32 -> 1723771.4 | I33: =I30+I32 -> 2361814.4 | J33: =J30+J32 -> 2508482.7 | K33: =K30+K32 -> 2584409.2 | L33: =L30+L32 -> 2662649.5 | M33: =M30+M32 -> 2742973 | N33: =N30+N32 -> 2826051.2
B34: DSCR
B35: Forward 12 Month NOI | G35: =IF(G7<=Assumptions!$B$35,H30,0) -> 1723771.4 | H35: =IF(H7<=Assumptions!$B$35,SUM('Annual Summary'!I30:I30),0) -> 2361814.4 | I35: =IF(I7<=Assumptions!$B$35,SUM('Annual Summary'!J30:J30),0) -> 2508482.7 | J35: =IF(J7<=Assumptions!$B$35,SUM('Annual Summary'!K30:K30),0) -> 2584409.2 | K35: =IF(K7<=Assumptions!$B$35,SUM('Annual Summary'!L30:L30),0) -> 2662649.5 | L35: =IF(L7<=Assumptions!$B$35,SUM('Annual Summary'!M30:M30),0) -> 2742973 | M35: =IF(M7<=Assumptions!$B$35,SUM('Annual Summary'!N30:N30),0) -> 2826051.2
B36: Margin | D36: =D30/D20 -> 0.34826051 | G36: =G30/G20 -> 0.38117919 | H36: =H30/H20 -> 0.44603944 | I36: =I30/I20 -> 0.51518503 | J36: =J30/J20 -> 0.52266206 | K36: =K30/K20 -> 0.522798 | L36: =L30/L20 -> 0.52293705 | M36: =M30/M20 -> 0.52302171
B38: ACQUISITION & SALE
B39: Purchase Price | F39: =-Assumptions!$B$32 -> -20000000 | G39: =-Assumptions!$B$32*(G8='Annual Summary'!$D$3) -> 0 | H39: =-Assumptions!$B$32*(H8='Annual Summary'!$D$3) -> 0 | I39: =-Assumptions!$B$32*(I8='Annual Summary'!$D$3) -> 0 | J39: =-Assumptions!$B$32*(J8='Annual Summary'!$D$3) -> 0 | K39: =-Assumptions!$B$32*(K8='Annual Summary'!$D$3) -> 0 | L39: =-Assumptions!$B$32*(L8='Annual Summary'!$D$3) -> 0 | M39: =-Assumptions!$B$32*(M8='Annual Summary'!$D$3) -> 0
B40: Acquisition Closing Costs | F40: =F39*Assumptions!B33 -> -400000 | G40: =G39*Assumptions!$C$33 -> 0 | H40: =H39*Assumptions!$C$33 -> 0 | I40: =I39*Assumptions!$C$33 -> 0 | J40: =J39*Assumptions!$C$33 -> 0 | K40: =K39*Assumptions!$C$33 -> 0 | L40: =L39*Assumptions!$C$33 -> 0 | M40: =M39*Assumptions!$C$33 -> 0
B41: Sales Proceeds | F41: =F$35/Assumptions!$B$36*(F8=$D$4) -> 0 | G41: =G$35/Assumptions!$B$36*(G8=$D$4) -> 0 | H41: =H$35/Assumptions!$B$36*(H8=$D$4) -> 0 | I41: =I$35/Assumptions!$B$36*(I8=$D$4) -> 0 | J41: =J$35/Assumptions!$B$36*(J8=$D$4) -> 0 | K41: =K$35/Assumptions!$B$36*(K8=$D$4) -> 0 | L41: =L$35/Assumptions!$B$36*(L8=$D$4) -> 0 | M41: =M$35/Assumptions!$B$36*(M8=$D$4) -> 51382748
B42: Exit Closing Costs | F42: =F41*Assumptions!$B$34 -> 0 | G42: =G41*Assumptions!$B$34 -> 0 | H42: =H41*Assumptions!$B$34 -> 0 | I42: =I41*Assumptions!$B$34 -> 0 | J42: =J41*Assumptions!$B$34 -> 0 | K42: =K41*Assumptions!$B$34 -> 0 | L42: =L41*Assumptions!$B$34 -> 0 | M42: =-M41*Assumptions!$B$34 -> -1027655
B43: Total Purchase & Sale | F43: =SUM(F39:F42) -> -20400000 | G43: =SUM(G39:G42) -> 0 | H43: =SUM(H39:H42) -> 0 | I43: =SUM(I39:I42) -> 0 | J43: =SUM(J39:J42) -> 0 | K43: =SUM(K39:K42) -> 0 | L43: =SUM(L39:L42) -> 0 | M43: =SUM(M39:M42) -> 50355093
B45: UNLEVERED CASH FLOW | F45: =F43+F33 -> -20400000 | G45: =G43+G33 -> 1184953.9 | H45: =H43+H33 -> 1723771.4 | I45: =I43+I33 -> 2361814.4 | J45: =J43+J33 -> 2508482.7 | K45: =K43+K33 -> 2584409.2 | L45: =L43+L33 -> 2662649.5 | M45: =M43+M33 -> 53098066
B47: UNLEVERED IRR | D47: =XIRR(F45:M45,F8:M8) -> 0.21081998
...
